<?xml version="1.0" ?>
<robot name="my_subsystem">
  <link name="arm">
    <visual>
      <geometry>
        <mesh filename="../examples/simple_arm/meshes/arm.obj"/>
      </geometry>
    </visual>
    <collision>
      <geometry>
        <mesh filename="../examples/simple_arm/meshes/arm.obj"/>
      </geometry>
    </collision>
    <inertial>
      <origin xyz="0.0 0.0 0.0" rpy="0 0 0"/>
      <mass value="1.0"/>
      <inertia ixx="0.01" ixy="0.0" ixz="0.0" iyy="0.01" iyz="0.0" izz="0.01"/>
    </inertial>
  </link>
  <link name="base">
    <visual>
      <geometry>
        <mesh filename="../examples/simple_arm/meshes/base.obj"/>
      </geometry>
    </visual>
    <collision>
      <geometry>
        <mesh filename="../examples/simple_arm/meshes/base.obj"/>
      </geometry>
    </collision>
    <inertial>
      <origin xyz="0.0 0.0 0.0" rpy="0 0 0"/>
      <mass value="1.0"/>
      <inertia ixx="0.01" ixy="0.0" ixz="0.0" iyy="0.01" iyz="0.0" izz="0.01"/>
    </inertial>
  </link>
  <joint name="joint_1" type="revolute">
    <parent link="arm"/>
    <child link="base"/>
    <origin xyz="0.0 0.0 0.1" rpy="0 0 0"/>
    <axis xyz="0.0 0.0 1.0"/>
    <limit lower="-1000000.0" upper="1000000.0" velocity="1000.0" effort="100.0"/>
  </joint>
</robot>
