<?xml version="1.0" ?>
<robot name="SimpleSim_Example">
  <link name="Elevator_Base">
    <visual>
      <geometry>
        <mesh filename="../generated_projects/SimpleSim_Example/meshes/Elevator_Base.stl"/>
      </geometry>
    </visual>
    <collision>
      <geometry>
        <mesh filename="../generated_projects/SimpleSim_Example/meshes/Elevator_Base.stl"/>
      </geometry>
    </collision>
    <inertial>
      <origin xyz="8.627819642385304e-05 0.008932690907972227 0.7470979155880756" rpy="0 0 0"/>
      <mass value="4.552363181200548"/>
      <inertia ixx="0.04552363181200548" ixy="0.0" ixz="0.0" iyy="0.04552363181200548" iyz="0.0" izz="0.04552363181200548"/>
    </inertial>
  </link>
  <link name="Carriage">
    <visual>
      <geometry>
        <mesh filename="../generated_projects/SimpleSim_Example/meshes/Carriage.stl"/>
      </geometry>
    </visual>
    <collision>
      <geometry>
        <mesh filename="../generated_projects/SimpleSim_Example/meshes/Carriage.stl"/>
      </geometry>
    </collision>
    <inertial>
      <origin xyz="-0.01975106726280527 -0.028267282854895083 0.07868671260021018" rpy="0 0 0"/>
      <mass value="1.9031493208779748"/>
      <inertia ixx="0.01903149320877975" ixy="0.0" ixz="0.0" iyy="0.01903149320877975" iyz="0.0" izz="0.01903149320877975"/>
    </inertial>
  </link>
  <joint name="Elevator_Joint" type="prismatic">
    <parent link="Elevator_Base"/>
    <child link="Carriage"/>
    <origin xyz="-0.00983239453319071 -0.009667295973461429 0.4128923140941429" rpy="0 0 0"/>
    <axis xyz="0.0 0.0 1.0"/>
    <limit lower="0.0" upper="4.0" velocity="10.0" effort="100.0"/>
    <dynamics damping="0.5" friction="0.0"/>
  </joint>
</robot>
