<?xml version="1.0" ?>
<robot name="SimpleSim_Example">
  <link name="Base">
    <visual>
      <geometry>
        <mesh filename="../meshes/Base.stl"/>
      </geometry>
    </visual>
    <collision>
      <geometry>
        <mesh filename="../meshes/Base.stl"/>
      </geometry>
    </collision>
    <inertial>
      <origin xyz="-0.002641044414812037 0.013926823992161476 0.7608089674550639" rpy="0 0 0"/>
      <mass value="5.095193188971689"/>
      <inertia ixx="0.05095193188971689" ixy="0.0" ixz="0.0" iyy="0.05095193188971689" iyz="0.0" izz="0.05095193188971689"/>
    </inertial>
  </link>
  <link name="Carriage">
    <visual>
      <geometry>
        <mesh filename="../meshes/Carriage.stl"/>
      </geometry>
    </visual>
    <collision>
      <geometry>
        <mesh filename="../meshes/Carriage.stl"/>
      </geometry>
    </collision>
    <inertial>
      <origin xyz="-7.152180085219333e-17 2.81764638280426e-18 0.11429999999999994" rpy="0 0 0"/>
      <mass value="1.06836643263247"/>
      <inertia ixx="0.0106836643263247" ixy="0.0" ixz="0.0" iyy="0.0106836643263247" iyz="0.0" izz="0.0106836643263247"/>
    </inertial>
  </link>
  <joint name="Elevator" type="prismatic">
    <parent link="Base"/>
    <child link="Carriage"/>
    <origin xyz="-0.0013205222074060543 0.00696341199608074 0.4375544837275319" rpy="0 0 0"/>
    <axis xyz="0.0 0.0 1.0"/>
    <limit lower="-1.0" upper="1.0" velocity="10.0" effort="100.0"/>
    <dynamics damping="10.0" friction="0.0"/>
  </joint>
</robot>
