<?xml version="1.0" ?>
<robot name="simple_arm">
  <link name="base">
    <visual>
      <geometry>
        <mesh filename="C:\Users\sadra\ICS4U\ICS4U-Summative\examples\simple_arm\examples\simple_arm\meshes\base.obj"/>
      </geometry>
    </visual>
    <collision>
      <geometry>
        <mesh filename="C:\Users\sadra\ICS4U\ICS4U-Summative\examples\simple_arm\examples\simple_arm\meshes\base.obj"/>
      </geometry>
    </collision>
    <inertial>
      <origin xyz="0.0 0.0 0.05" rpy="0 0 0"/>
      <mass value="2.0"/>
      <inertia ixx="0.02" ixy="0.0" ixz="0.0" iyy="0.02" iyz="0.0" izz="0.02"/>
    </inertial>
  </link>
  <link name="arm">
    <visual>
      <geometry>
        <mesh filename="C:\Users\sadra\ICS4U\ICS4U-Summative\examples\simple_arm\examples\simple_arm\meshes\arm.obj"/>
      </geometry>
    </visual>
    <collision>
      <geometry>
        <mesh filename="C:\Users\sadra\ICS4U\ICS4U-Summative\examples\simple_arm\examples\simple_arm\meshes\arm.obj"/>
      </geometry>
    </collision>
    <inertial>
      <origin xyz="0.0 0.0 0.25" rpy="0 0 0"/>
      <mass value="1.5"/>
      <inertia ixx="0.015" ixy="0.0" ixz="0.0" iyy="0.015" iyz="0.0" izz="0.015"/>
    </inertial>
  </link>
  <joint name="shoulder" type="revolute">
    <parent link="base"/>
    <child link="arm"/>
    <origin xyz="0.0 0.0 0.1" rpy="0 0 0"/>
    <axis xyz="0.0 0.0 1.0"/>
    <limit lower="-1000000.0" upper="1000000.0" velocity="1000.0" effort="100.0"/>
  </joint>
</robot>
